File: src/parser/__tests__/data/ARXPS.vms
VAMAS Surface Chemical Analysis Standard Data Transfer Format 1988 May 4

Kratos Axis


0
MAP
REGULAR
1
0
0
0
4
Angle
degree
PositionX [mm]
n
PositionY [mm]
n
PositionZ [mm]
n
0
0
0
0
15
O 1s
Al_foil_insulated
2020
2
6
1
20
30
1
42
File: C:\ESCApe\Data\Training\20200205_Al_foil_ARXPS.experiment
Creation
Created by : DESKTOP-MI6NA2R\kratos
Date created : 06/02/2020 01:20
Computer : DESKTOP-MI6NA2R
Location
Location ID : Al_foil_insulated
Sample : Al_foil_insulated
Description : (55.076,11.860,-0.296)mm
Tilt : 0.00
Charge Neutraliser : On
Filament Current : 0.5A
Filament Bias : 1V
Charge Balance : 4.9V
Settings
Excitation
Mode : XPS - monochromatic
Tuning : Spectroscopy
Emission current : 15.00mA
Anode library : Al
ESCA modes
Collimation : Slot
Lens : Hybrid
Resolution : 20.00
Scan
Deflection : (0.000, 0.000)mm
O 1s : 943.690-963.690eV, Sweeps 1
Start : 943.690eV
End : 963.690eV
Centre : 953.690eV
Width : 20.000eV
Step size : 0.100eV
Number Steps : 200
Dwell time : 299ms
Sweep time : 60s
Sweeps : 1
Target quality : 100
Instrument Conditions
Work function : -4.50
Acquisition Conditions
X-ray Power : 225.00W
Quality : 404.96
XPS
0
0
0
55.0755
11.8598125
-0.2956015625
Al
1486.69
100
0
0
0
0
0
0
FAT
160
0
-4.5
0
0
0
0
0
O
1s
0
Kinetic Energy
eV
943.69
0.1
2
Intensity
d
Transmission
d
pulse counting
0.298507004976273
1
0
0
0
0
0
402
0
0
0
0
1678
0.694879764806946
1729
0.694884779682697
1716
0.694889794558448
1730
0.694894809434199
1703
0.694899824309951
1744
0.694904839185702
1694
0.694909854061453
1659
0.694914868937204
1681
0.694919883812955
1688
0.694924898688706
1594
0.694929913564458
1665
0.694934928440209
1654
0.69493994331596
1668
0.694944958191711
1653
0.694949973067462
1659
0.694954987943213
1646
0.694960002818964
1623
0.694965017694716
1559
0.694970032570467
1601
0.694975047446218
1581
0.694980062321969
1525
0.69498507719772
1525
0.694990092073471
1555
0.694995106949223
1588
0.695000121824974
1538
0.695005136700725
1518
0.695010151576476
1570
0.695015166452227
1515
0.695020181327978
1492
0.695025196203729
1563
0.695030211079481
1462
0.695035225955232
1508
0.695040240830983
1480
0.695045255706734
1474
0.695050270582485
1464
0.695055285458236
1454
0.695060300333987
1475
0.695065315209739
1451
0.69507033008549
1391
0.695075344961241
1330
0.695080359836992
1414
0.695085374712743
1393
0.695090389588494
1407
0.695095404464246
1401
0.695100419339997
1374
0.695105434215748
1366
0.695110449091499
1398
0.69511546396725
1380
0.695120478843001
1360
0.695125493718752
1357
0.695130508594504
1355
0.695135523470255
1308
0.695140538346006
1262
0.695145553221757
1297
0.695150568097508
1308
0.695155582973259
1310
0.695160597849011
1276
0.695165612724762
1276
0.695170627600513
1280
0.695175642476264
1248
0.695180657352015
1277
0.695185672227766
1240
0.695190687103517
1195
0.695195701979269
1197
0.69520071685502
1253
0.695205731730771
1253
0.695210746606522
1246
0.695215761482273
1195
0.695220776358024
1146
0.695225791233775
1201
0.695230806109527
1145
0.695235820985278
1113
0.695240835861029
1126
0.69524585073678
1141
0.695250865612531
1086
0.695255880488282
1125
0.695260895364034
1058
0.695265910239785
1057
0.695270925115536
1092
0.695275939991287
1025
0.695280954867038
1036
0.695285969742789
1022
0.69529098461854
1067
0.695295999494292
1075
0.695301014370043
962
0.695306029245794
1009
0.695311044121545
1003
0.695316058997296
959
0.695321073873047
973
0.695326088748799
934
0.69533110362455
952
0.695336118500301
1003
0.695341133376052
944
0.695346148251803
917
0.695351163127554
940
0.695356178003305
960
0.695361192879057
928
0.695366207754808
931
0.695371222630559
895
0.69537623750631
964
0.695381252382061
954
0.695386267257812
954
0.695391282133563
942
0.695396297009315
914
0.695401311885066
928
0.695406326760817
961
0.695411341636568
934
0.695416356512319
953
0.69542137138807
919
0.695426386263822
906
0.695431401139573
919
0.695436416015324
873
0.695441430891075
946
0.695446445766826
966
0.695451460642577
917
0.695456475518328
931
0.69546149039408
946
0.695466505269831
963
0.695471520145582
957
0.695476535021333
1003
0.695481549897084
980
0.695486564772835
1038
0.695491579648587
990
0.695496594524338
1046
0.695501609400089
1053
0.69550662427584
1105
0.695511639151591
1165
0.695516654027342
1178
0.695521668903093
1282
0.695526683778845
1395
0.695531698654596
1470
0.695536713530347
1508
0.695541728406098
1619
0.695546743281849
1783
0.6955517581576
1928
0.695556773033352
2200
0.695561787909103
2502
0.695566802784854
2775
0.695571817660605
3134
0.695576832536356
3585
0.695581847412107
4118
0.695586862287858
4499
0.69559187716361
5100
0.695596892039361
5716
0.695601906915112
6340
0.695606921790863
7153
0.695611936666614
7858
0.695616951542365
8577
0.695621966418116
9298
0.695626981293868
10064
0.695631996169619
10648
0.69563701104537
11319
0.695642025921121
12010
0.695647040796872
12493
0.695652055672623
12838
0.695657070548375
13291
0.695662085424126
13721
0.695667100299877
13800
0.695672115175628
13806
0.695677130051379
13835
0.69568214492713
13787
0.695687159802881
13635
0.695692174678633
13457
0.695697189554384
12793
0.695702204430135
12415
0.695707219305886
11463
0.695712234181637
10541
0.695717249057388
9747
0.69572226393314
8841
0.695727278808891
7896
0.695732293684642
6961
0.695737308560393
6087
0.695742323436144
5143
0.695747338311895
4454
0.695752353187646
3882
0.695757368063398
3298
0.695762382939149
2778
0.6957673978149
2377
0.695772412690651
1975
0.695777427566402
1730
0.695782442442153
1519
0.695787457317904
1310
0.695792472193656
1212
0.695797487069407
1149
0.695802501945158
1073
0.695807516820909
998
0.69581253169666
980
0.695817546572411
924
0.695822561448163
928
0.695827576323914
847
0.695832591199665
873
0.695837606075416
890
0.695842620951167
883
0.695847635826918
882
0.695852650702669
850
0.695857665578421
847
0.695862680454172
822
0.695867695329923
812
0.695872710205674
870
0.695877725081425
800
0.695882739957176
C 1s
Al_foil_insulated
2020
2
6
1
20
30
1
42
File: C:\ESCApe\Data\Training\20200205_Al_foil_ARXPS.experiment
Creation
Created by : DESKTOP-MI6NA2R\kratos
Date created : 06/02/2020 01:20
Computer : DESKTOP-MI6NA2R
Location
Location ID : Al_foil_insulated
Sample : Al_foil_insulated
Description : (55.076,11.860,-0.296)mm
Tilt : 0.00
Charge Neutraliser : On
Filament Current : 0.5A
Filament Bias : 1V
Charge Balance : 4.9V
Settings
Excitation
Mode : XPS - monochromatic
Tuning : Spectroscopy
Emission current : 15.00mA
Anode library : Al
ESCA modes
Collimation : Slot
Lens : Hybrid
Resolution : 20.00
Scan
Deflection : (0.000, 0.000)mm
C 1s : 1191.690-1211.690eV, Sweeps 1
Start : 1191.690eV
End : 1211.690eV
Centre : 1201.690eV
Width : 20.000eV
Step size : 0.100eV
Number Steps : 200
Dwell time : 299ms
Sweep time : 60s
Sweeps : 1
Target quality : 100
Instrument Conditions
Work function : -4.50
Acquisition Conditions
X-ray Power : 225.00W
Quality : 100.82
XPS
0
0
0
55.0755
11.8598125
-0.2956015625
Al
1486.69
100
0
0
0
0
0
0
FAT
160
0
-4.5
0
0
0
0
0
C
1s
0
Kinetic Energy
eV
1191.69
0.1
2
Intensity
d
Transmission
d
pulse counting
0.298507988452911
1
0
0
0
0
0
402
0
0
0
0
877
0.677919839607315
848
0.677933989241674
926
0.677948138876032
907
0.67796228851039
892
0.677976438144748
917
0.677990587779106
897
0.678004737413464
898
0.678018887047823
869
0.678033036682181
857
0.678047186316539
867
0.678061335950897
862
0.678075485585255
900
0.678089635219613
859
0.678103784853971
880
0.678117934488329
878
0.678132084122688
902
0.678146233757046
886
0.678160383391404
843
0.678174533025762
832
0.67818868266012
865
0.678202832294478
857
0.678216981928837
857
0.678231131563195
869
0.678245281197553
892
0.678259430831911
864
0.678273580466269
900
0.678287730100627
848
0.678301879734985
835
0.678316029369343
886
0.678330179003702
882
0.67834432863806
857
0.678358478272418
846
0.678372627906776
828
0.678386777541134
840
0.678400927175492
854
0.67841507680985
837
0.678429226444209
852
0.678443376078567
826
0.678457525712925
873
0.678471675347283
834
0.678485824981641
903
0.678499974615999
892
0.678514124250357
852
0.678528273884716
873
0.678542423519074
805
0.678556573153432
807
0.67857072278779
815
0.678584872422148
854
0.678599022056506
861
0.678613171690864
851
0.678627321325223
880
0.678641470959581
851
0.678655620593939
840
0.678669770228297
861
0.678683919862655
864
0.678698069497013
820
0.678712219131371
828
0.67872636876573
838
0.678740518400088
872
0.678754668034446
816
0.678768817668804
801
0.678782967303162
846
0.67879711693752
823
0.678811266571878
827
0.678825416206237
825
0.678839565840595
831
0.678853715474953
873
0.678867865109311
874
0.678882014743669
859
0.678896164378027
792
0.678910314012385
814
0.678924463646744
858
0.678938613281102
874
0.67895276291546
775
0.678966912549818
857
0.678981062184176
852
0.678995211818534
830
0.679009361452892
817
0.679023511087251
856
0.679037660721609
859
0.679051810355967
880
0.679065959990325
886
0.679080109624683
831
0.679094259259041
804
0.679108408893399
823
0.679122558527757
890
0.679136708162116
880
0.679150857796474
906
0.679165007430832
885
0.67917915706519
866
0.679193306699548
931
0.679207456333906
945
0.679221605968265
903
0.679235755602623
917
0.679249905236981
976
0.679264054871339
1023
0.679278204505697
1036
0.679292354140055
1020
0.679306503774413
1036
0.679320653408771
1071
0.67933480304313
1063
0.679348952677488
1013
0.679363102311846
995
0.679377251946204
1053
0.679391401580562
1076
0.67940555121492
1045
0.679419700849278
966
0.679433850483637
1013
0.679448000117995
987
0.679462149752353
987
0.679476299386711
956
0.679490449021069
955
0.679504598655427
983
0.679518748289785
939
0.679532897924144
948
0.679547047558502
974
0.67956119719286
955
0.679575346827218
967
0.679589496461576
1000
0.679603646095934
1028
0.679617795730292
1010
0.679631945364651
1000
0.679646094999009
979
0.679660244633367
1013
0.679674394267725
1076
0.679688543902083
1123
0.679702693536441
1166
0.679716843170799
1154
0.679730992805158
1197
0.679745142439516
1323
0.679759292073874
1407
0.679773441708232
1468
0.67978759134259
1586
0.679801740976948
1665
0.679815890611306
1859
0.679830040245665
2022
0.679844189880023
2320
0.679858339514381
2524
0.679872489148739
2694
0.679886638783097
2821
0.679900788417455
2923
0.679914938051813
2946
0.679929087686172
2972
0.67994323732053
2857
0.679957386954888
2629
0.679971536589246
2489
0.679985686223604
2293
0.679999835857962
1993
0.68001398549232
1802
0.680028135126679
1531
0.680042284761037
1406
0.680056434395395
1236
0.680070584029753
1109
0.680084733664111
1029
0.680098883298469
984
0.680113032932827
917
0.680127182567186
901
0.680141332201544
882
0.680155481835902
875
0.68016963147026
827
0.680183781104618
846
0.680197930738976
806
0.680212080373334
779
0.680226230007693
832
0.680240379642051
789
0.680254529276409
825
0.680268678910767
795
0.680282828545125
817
0.680296978179483
835
0.680311127813841
833
0.680325277448199
854
0.680339427082558
797
0.680353576716916
787
0.680367726351274
792
0.680381875985632
808
0.68039602561999
834
0.680410175254348
831
0.680424324888707
816
0.680438474523065
796
0.680452624157423
820
0.680466773791781
845
0.680480923426139
803
0.680495073060497
790
0.680509222694855
828
0.680523372329213
830
0.680537521963572
825
0.68055167159793
821
0.680565821232288
806
0.680579970866646
823
0.680594120501004
789
0.680608270135362
798
0.68062241976972
803
0.680636569404079
801
0.680650719038437
786
0.680664868672795
801
0.680679018307153
803
0.680693167941511
837
0.680707317575869
826
0.680721467210227
834
0.680735616844586
812
0.680749766478944
Al 2p
Al_foil_insulated
2020
2
6
1
20
30
1
42
File: C:\ESCApe\Data\Training\20200205_Al_foil_ARXPS.experiment
Creation
Created by : DESKTOP-MI6NA2R\kratos
Date created : 06/02/2020 01:20
Computer : DESKTOP-MI6NA2R
Location
Location ID : Al_foil_insulated
Sample : Al_foil_insulated
Description : (55.076,11.860,-0.296)mm
Tilt : 0.00
Charge Neutraliser : On
Filament Current : 0.5A
Filament Bias : 1V
Charge Balance : 4.9V
Settings
Excitation
Mode : XPS - monochromatic
Tuning : Spectroscopy
Emission current : 15.00mA
Anode library : Al
ESCA modes
Collimation : Slot
Lens : Hybrid
Resolution : 20.00
Scan
Deflection : (0.000, 0.000)mm
Al 2p : 1400.690-1420.690eV, Sweeps 1
Start : 1400.690eV
End : 1420.690eV
Centre : 1410.690eV
Width : 20.000eV
Step size : 0.100eV
Number Steps : 200
Dwell time : 299ms
Sweep time : 60s
Sweeps : 1
Target quality : 100
Instrument Conditions
Work function : -4.50
Acquisition Conditions
X-ray Power : 225.00W
Quality : 145.79
XPS
0
0
0
55.0755
11.8598125
-0.2956015625
Al
1486.69
100
0
0
0
0
0
0
FAT
160
0
-4.5
0
0
0
0
0
Al
2p
0
Kinetic Energy
eV
1400.69
0.1
2
Intensity
d
Transmission
d
pulse counting
0.298507004976273
1
0
0
0
0
0
402
0
0
0
0
431
0.672157671707001
410
0.672171187331118
405
0.672184702955234
426
0.672198218579351
413
0.672211734203467
429
0.672225249827584
429
0.6722387654517
437
0.672252281075817
443
0.672265796699933
486
0.67227931232405
475
0.672292827948166
489
0.672306343572283
458
0.672319859196399
477
0.672333374820516
491
0.672346890444633
489
0.672360406068749
480
0.672373921692866
470
0.672387437316982
458
0.672400952941099
467
0.672414468565215
512
0.672427984189332
527
0.672441499813448
514
0.672455015437565
522
0.672468531061681
547
0.672482046685798
589
0.672495562309914
583
0.672509077934031
609
0.672522593558147
607
0.672536109182264
642
0.67254962480638
634
0.672563140430497
625
0.672576656054614
643
0.67259017167873
607
0.672603687302847
549
0.672617202926963
512
0.67263071855108
479
0.672644234175196
449
0.672657749799313
381
0.672671265423429
343
0.672684781047546
326
0.672698296671662
313
0.672711812295779
307
0.672725327919895
305
0.672738843544012
308
0.672752359168128
273
0.672765874792245
250
0.672779390416362
260
0.672792906040478
251
0.672806421664595
234
0.672819937288711
217
0.672833452912828
219
0.672846968536944
203
0.672860484161061
228
0.672873999785177
236
0.672887515409294
234
0.67290103103341
211
0.672914546657527
192
0.672928062281643
203
0.67294157790576
192
0.672955093529876
187
0.672968609153993
185
0.672982124778109
207
0.672995640402226
209
0.673009156026343
199
0.673022671650459
186
0.673036187274576
181
0.673049702898692
193
0.673063218522809
188
0.673076734146925
200
0.673090249771042
187
0.673103765395158
187
0.673117281019275
191
0.673130796643391
186
0.673144312267508
173
0.673157827891624
172
0.673171343515741
169
0.673184859139857
172
0.673198374763974
167
0.673211890388091
169
0.673225406012207
153
0.673238921636324
152
0.67325243726044
158
0.673265952884557
137
0.673279468508673
149
0.67329298413279
158
0.673306499756906
144
0.673320015381023
159
0.673333531005139
150
0.673347046629256
163
0.673360562253372
145
0.673374077877489
160
0.673387593501605
163
0.673401109125722
144
0.673414624749839
140
0.673428140373955
138
0.673441655998072
127
0.673455171622188
143
0.673468687246305
132
0.673482202870421
136
0.673495718494538
150
0.673509234118654
142
0.673522749742771
149
0.673536265366887
153
0.673549780991004
139
0.67356329661512
148
0.673576812239237
153
0.673590327863353
147
0.67360384348747
153
0.673617359111587
120
0.673630874735703
132
0.67364439035982
140
0.673657905983936
134
0.673671421608053
114
0.673684937232169
119
0.673698452856286
147
0.673711968480402
149
0.673725484104519
133
0.673738999728635
151
0.673752515352752
145
0.673766030976868
146
0.673779546600985
145
0.673793062225101
141
0.673806577849218
137
0.673820093473335
136
0.673833609097451
138
0.673847124721568
154
0.673860640345684
152
0.673874155969801
141
0.673887671593917
141
0.673901187218034
138
0.67391470284215
141
0.673928218466267
149
0.673941734090383
164
0.6739552497145
167
0.673968765338616
162
0.673982280962733
153
0.673995796586849
195
0.674009312210966
204
0.674022827835082
220
0.674036343459199
222
0.674049859083316
284
0.674063374707432
310
0.674076890331549
337
0.674090405955665
396
0.674103921579782
495
0.674117437203898
606
0.674130952828015
723
0.674144468452131
853
0.674157984076248
1014
0.674171499700364
1179
0.674185015324481
1368
0.674198530948597
1630
0.674212046572714
1758
0.67422556219683
2030
0.674239077820947
2200
0.674252593445064
2341
0.67426610906918
2411
0.674279624693297
2459
0.674293140317413
2401
0.67430665594153
2335
0.674320171565646
2249
0.674333687189763
2105
0.674347202813879
1878
0.674360718437996
1686
0.674374234062112
1467
0.674387749686229
1247
0.674401265310345
1124
0.674414780934462
928
0.674428296558578
782
0.674441812182695
650
0.674455327806812
550
0.674468843430928
466
0.674482359055045
431
0.674495874679161
384
0.674509390303278
400
0.674522905927394
409
0.674536421551511
412
0.674549937175627
501
0.674563452799744
647
0.67457696842386
925
0.674590484047977
1245
0.674603999672093
1384
0.67461751529621
1463
0.674631030920327
1523
0.674644546544443
1815
0.67465806216856
1880
0.674671577792676
1420
0.674685093416793
798
0.674698609040909
351
0.674712124665026
171
0.674725640289142
127
0.674739155913259
122
0.674752671537375
108
0.674766187161492
101
0.674779702785608
96
0.674793218409725
87
0.674806734033841
84
0.674820249657958
100
0.674833765282075
94
0.674847280906191
82
0.674860796530308
O 1s
Al_foil_insulated
2020
2
6
1
24
37
1
42
File: C:\ESCApe\Data\Training\20200205_Al_foil_ARXPS.experiment
Creation
Created by : DESKTOP-MI6NA2R\kratos
Date created : 06/02/2020 01:24
Computer : DESKTOP-MI6NA2R
Location
Location ID : Al_foil_insulated
Sample : Al_foil_insulated
Description : (55.076,11.860,-0.296)mm
Tilt : 40.00
Charge Neutraliser : On
Filament Current : 0.5A
Filament Bias : 1V
Charge Balance : 4.9V
Settings
Excitation
Mode : XPS - monochromatic
Tuning : Spectroscopy
Emission current : 15.00mA
Anode library : Al
ESCA modes
Collimation : Slot
Lens : Hybrid
Resolution : 20.00
Scan
Deflection : (0.000, 0.000)mm
O 1s : 943.690-963.690eV, Sweeps 1
Start : 943.690eV
End : 963.690eV
Centre : 953.690eV
Width : 20.000eV
Step size : 0.100eV
Number Steps : 200
Dwell time : 299ms
Sweep time : 60s
Sweeps : 1
Target quality : 100
Instrument Conditions
Work function : -4.50
Acquisition Conditions
X-ray Power : 225.00W
Quality : 341.85
XPS
0
0
40
55.0755
11.8598125
-0.2956015625
Al
1486.69
100
0
0
0
0
0
0
FAT
160
0
-4.5
0
0
0
0
0
O
1s
0
Kinetic Energy
eV
943.69
0.1
2
Intensity
d
Transmission
d
pulse counting
0.298507004976273
1
0
0
0
0
0
402
0
0
0
0
1098
0.694879764806946
1117
0.694884779682697
1086
0.694889794558448
1096
0.694894809434199
1115
0.694899824309951
1087
0.694904839185702
1022
0.694909854061453
1079
0.694914868937204
1094
0.694919883812955
1039
0.694924898688706
1065
0.694929913564458
1002
0.694934928440209
1041
0.69493994331596
1058
0.694944958191711
991
0.694949973067462
1027
0.694954987943213
1055
0.694960002818964
1007
0.694965017694716
1000
0.694970032570467
1032
0.694975047446218
1019
0.694980062321969
981
0.69498507719772
967
0.694990092073471
999
0.694995106949223
955
0.695000121824974
916
0.695005136700725
956
0.695010151576476
980
0.695015166452227
976
0.695020181327978
977
0.695025196203729
903
0.695030211079481
885
0.695035225955232
916
0.695040240830983
896
0.695045255706734
882
0.695050270582485
919
0.695055285458236
906
0.695060300333987
901
0.695065315209739
884
0.69507033008549
849
0.695075344961241
836
0.695080359836992
867
0.695085374712743
844
0.695090389588494
847
0.695095404464246
822
0.695100419339997
792
0.695105434215748
821
0.695110449091499
837
0.69511546396725
815
0.695120478843001
834
0.695125493718752
826
0.695130508594504
786
0.695135523470255
787
0.695140538346006
780
0.695145553221757
764
0.695150568097508
798
0.695155582973259
766
0.695160597849011
724
0.695165612724762
752
0.695170627600513
732
0.695175642476264
727
0.695180657352015
760
0.695185672227766
738
0.695190687103517
707
0.695195701979269
704
0.69520071685502
731
0.695205731730771
732
0.695210746606522
700
0.695215761482273
710
0.695220776358024
723
0.695225791233775
689
0.695230806109527
665
0.695235820985278
683
0.695240835861029
646
0.69524585073678
652
0.695250865612531
629
0.695255880488282
641
0.695260895364034
622
0.695265910239785
644
0.695270925115536
642
0.695275939991287
610
0.695280954867038
613
0.695285969742789
623
0.69529098461854
612
0.695295999494292
609
0.695301014370043
636
0.695306029245794
580
0.695311044121545
551
0.695316058997296
557
0.695321073873047
553
0.695326088748799
549
0.69533110362455
589
0.695336118500301
573
0.695341133376052
555
0.695346148251803
519
0.695351163127554
517
0.695356178003305
515
0.695361192879057
530
0.695366207754808
535
0.695371222630559
522
0.69537623750631
533
0.695381252382061
550
0.695386267257812
528
0.695391282133563
520
0.695396297009315
518
0.695401311885066
511
0.695406326760817
559
0.695411341636568
533
0.695416356512319
541
0.69542137138807
554
0.695426386263822
523
0.695431401139573
536
0.695436416015324
499
0.695441430891075
536
0.695446445766826
546
0.695451460642577
572
0.695456475518328
574
0.69546149039408
554
0.695466505269831
532
0.695471520145582
572
0.695476535021333
590
0.695481549897084
622
0.695486564772835
630
0.695491579648587
648
0.695496594524338
638
0.695501609400089
637
0.69550662427584
667
0.695511639151591
740
0.695516654027342
770
0.695521668903093
821
0.695526683778845
858
0.695531698654596
960
0.695536713530347
1001
0.695541728406098
1085
0.695546743281849
1223
0.6955517581576
1413
0.695556773033352
1564
0.695561787909103
1770
0.695566802784854
2061
0.695571817660605
2244
0.695576832536356
2630
0.695581847412107
2878
0.695586862287858
3348
0.69559187716361
3720
0.695596892039361
4095
0.695601906915112
4470
0.695606921790863
4875
0.695611936666614
5336
0.695616951542365
5685
0.695621966418116
6010
0.695626981293868
6394
0.695631996169619
6739
0.69563701104537
6951
0.695642025921121
7182
0.695647040796872
7320
0.695652055672623
7528
0.695657070548375
7692
0.695662085424126
7812
0.695667100299877
7791
0.695672115175628
7786
0.695677130051379
7638
0.69568214492713
7419
0.695687159802881
7312
0.695692174678633
7167
0.695697189554384
6749
0.695702204430135
6427
0.695707219305886
5985
0.695712234181637
5544
0.695717249057388
5068
0.69572226393314
4501
0.695727278808891
4003
0.695732293684642
3478
0.695737308560393
3106
0.695742323436144
2706
0.695747338311895
2312
0.695752353187646
1968
0.695757368063398
1704
0.695762382939149
1426
0.6957673978149
1212
0.695772412690651
1053
0.695777427566402
908
0.695782442442153
823
0.695787457317904
761
0.695792472193656
702
0.695797487069407
634
0.695802501945158
573
0.695807516820909
534
0.69581253169666
533
0.695817546572411
517
0.695822561448163
496
0.695827576323914
493
0.695832591199665
492
0.695837606075416
524
0.695842620951167
512
0.695847635826918
511
0.695852650702669
527
0.695857665578421
527
0.695862680454172
509
0.695867695329923
469
0.695872710205674
479
0.695877725081425
485
0.695882739957176
C 1s
Al_foil_insulated
2020
2
6
1
24
37
1
42
File: C:\ESCApe\Data\Training\20200205_Al_foil_ARXPS.experiment
Creation
Created by : DESKTOP-MI6NA2R\kratos
Date created : 06/02/2020 01:24
Computer : DESKTOP-MI6NA2R
Location
Location ID : Al_foil_insulated
Sample : Al_foil_insulated
Description : (55.076,11.860,-0.296)mm
Tilt : 40.00
Charge Neutraliser : On
Filament Current : 0.5A
Filament Bias : 1V
Charge Balance : 4.9V
Settings
Excitation
Mode : XPS - monochromatic
Tuning : Spectroscopy
Emission current : 15.00mA
Anode library : Al
ESCA modes
Collimation : Slot
Lens : Hybrid
Resolution : 20.00
Scan
Deflection : (0.000, 0.000)mm
C 1s : 1191.690-1211.690eV, Sweeps 1
Start : 1191.690eV
End : 1211.690eV
Centre : 1201.690eV
Width : 20.000eV
Step size : 0.100eV
Number Steps : 200
Dwell time : 299ms
Sweep time : 60s
Sweeps : 1
Target quality : 100
Instrument Conditions
Work function : -4.50
Acquisition Conditions
X-ray Power : 225.00W
Quality : 110.27
XPS
0
0
40
55.0755
11.8598125
-0.2956015625
Al
1486.69
100
0
0
0
0
0
0
FAT
160
0
-4.5
0
0
0
0
0
C
1s
0
Kinetic Energy
eV
1191.69
0.1
2
Intensity
d
Transmission
d
pulse counting
0.298507988452911
1
0
0
0
0
0
402
0
0
0
0
536
0.677919839607315
508
0.677933989241674
518
0.677948138876032
488
0.67796228851039
489
0.677976438144748
509
0.677990587779106
553
0.678004737413464
514
0.678018887047823
514
0.678033036682181
526
0.678047186316539
532
0.678061335950897
522
0.678075485585255
527
0.678089635219613
487
0.678103784853971
478
0.678117934488329
490
0.678132084122688
479
0.678146233757046
487
0.678160383391404
485
0.678174533025762
544
0.67818868266012
504
0.678202832294478
514
0.678216981928837
504
0.678231131563195
523
0.678245281197553
528
0.678259430831911
515
0.678273580466269
470
0.678287730100627
483
0.678301879734985
518
0.678316029369343
476
0.678330179003702
504
0.67834432863806
494
0.678358478272418
510
0.678372627906776
527
0.678386777541134
510
0.678400927175492
493
0.67841507680985
519
0.678429226444209
476
0.678443376078567
441
0.678457525712925
457
0.678471675347283
500
0.678485824981641
492
0.678499974615999
476
0.678514124250357
478
0.678528273884716
478
0.678542423519074
507
0.678556573153432
509
0.67857072278779
494
0.678584872422148
476
0.678599022056506
479
0.678613171690864
486
0.678627321325223
484
0.678641470959581
472
0.678655620593939
496
0.678669770228297
499
0.678683919862655
509
0.678698069497013
503
0.678712219131371
487
0.67872636876573
495
0.678740518400088
500
0.678754668034446
491
0.678768817668804
510
0.678782967303162
487
0.67879711693752
468
0.678811266571878
490
0.678825416206237
471
0.678839565840595
474
0.678853715474953
483
0.678867865109311
473
0.678882014743669
474
0.678896164378027
471
0.678910314012385
475
0.678924463646744
503
0.678938613281102
478
0.67895276291546
483
0.678966912549818
504
0.678981062184176
483
0.678995211818534
480
0.679009361452892
499
0.679023511087251
493
0.679037660721609
533
0.679051810355967
491
0.679065959990325
530
0.679080109624683
528
0.679094259259041
538
0.679108408893399
515
0.679122558527757
524
0.679136708162116
521
0.679150857796474
554
0.679165007430832
539
0.67917915706519
556
0.679193306699548
576
0.679207456333906
597
0.679221605968265
578
0.679235755602623
593
0.679249905236981
589
0.679264054871339
607
0.679278204505697
590
0.679292354140055
620
0.679306503774413
643
0.679320653408771
656
0.67933480304313
659
0.679348952677488
645
0.679363102311846
627
0.679377251946204
643
0.679391401580562
602
0.67940555121492
620
0.679419700849278
597
0.679433850483637
610
0.679448000117995
592
0.679462149752353
586
0.679476299386711
549
0.679490449021069
569
0.679504598655427
578
0.679518748289785
551
0.679532897924144
571
0.679547047558502
553
0.67956119719286
579
0.679575346827218
573
0.679589496461576
622
0.679603646095934
610
0.679617795730292
608
0.679631945364651
637
0.679646094999009
647
0.679660244633367
697
0.679674394267725
718
0.679688543902083
717
0.679702693536441
763
0.679716843170799
835
0.679730992805158
838
0.679745142439516
890
0.679759292073874
1023
0.679773441708232
1110
0.67978759134259
1203
0.679801740976948
1338
0.679815890611306
1448
0.679830040245665
1619
0.679844189880023
1797
0.679858339514381
1959
0.679872489148739
2122
0.679886638783097
2188
0.679900788417455
2214
0.679914938051813
2123
0.679929087686172
2072
0.67994323732053
1975
0.679957386954888
1835
0.679971536589246
1576
0.679985686223604
1424
0.679999835857962
1308
0.68001398549232
1126
0.680028135126679
963
0.680042284761037
829
0.680056434395395
764
0.680070584029753
691
0.680084733664111
623
0.680098883298469
587
0.680113032932827
570
0.680127182567186
542
0.680141332201544
573
0.680155481835902
490
0.68016963147026
459
0.680183781104618
523
0.680197930738976
470
0.680212080373334
440
0.680226230007693
457
0.680240379642051
472
0.680254529276409
488
0.680268678910767
450
0.680282828545125
467
0.680296978179483
476
0.680311127813841
472
0.680325277448199
477
0.680339427082558
501
0.680353576716916
472
0.680367726351274
462
0.680381875985632
482
0.68039602561999
478
0.680410175254348
460
0.680424324888707
453
0.680438474523065
445
0.680452624157423
451
0.680466773791781
440
0.680480923426139
454
0.680495073060497
447
0.680509222694855
457
0.680523372329213
462
0.680537521963572
492
0.68055167159793
483
0.680565821232288
455
0.680579970866646
472
0.680594120501004
451
0.680608270135362
462
0.68062241976972
446
0.680636569404079
491
0.680650719038437
453
0.680664868672795
443
0.680679018307153
448
0.680693167941511
453
0.680707317575869
428
0.680721467210227
434
0.680735616844586
474
0.680749766478944
Al 2p
Al_foil_insulated
2020
2
6
1
24
37
1
42
File: C:\ESCApe\Data\Training\20200205_Al_foil_ARXPS.experiment
Creation
Created by : DESKTOP-MI6NA2R\kratos
Date created : 06/02/2020 01:24
Computer : DESKTOP-MI6NA2R
Location
Location ID : Al_foil_insulated
Sample : Al_foil_insulated
Description : (55.076,11.860,-0.296)mm
Tilt : 40.00
Charge Neutraliser : On
Filament Current : 0.5A
Filament Bias : 1V
Charge Balance : 4.9V
Settings
Excitation
Mode : XPS - monochromatic
Tuning : Spectroscopy
Emission current : 15.00mA
Anode library : Al
ESCA modes
Collimation : Slot
Lens : Hybrid
Resolution : 20.00
Scan
Deflection : (0.000, 0.000)mm
Al 2p : 1400.690-1420.690eV, Sweeps 1
Start : 1400.690eV
End : 1420.690eV
Centre : 1410.690eV
Width : 20.000eV
Step size : 0.100eV
Number Steps : 200
Dwell time : 299ms
Sweep time : 60s
Sweeps : 1
Target quality : 100
Instrument Conditions
Work function : -4.50
Acquisition Conditions
X-ray Power : 225.00W
Quality : 131.43
XPS
0
0
40
55.0755
11.8598125
-0.2956015625
Al
1486.69
100
0
0
0
0
0
0
FAT
160
0
-4.5
0
0
0
0
0
Al
2p
0
Kinetic Energy
eV
1400.69
0.1
2
Intensity
d
Transmission
d
pulse counting
0.298507004976273
1
0
0
0
0
0
402
0
0
0
0
215
0.672157671707001
208
0.672171187331118
229
0.672184702955234
248
0.672198218579351
211
0.672211734203467
234
0.672225249827584
222
0.6722387654517
238
0.672252281075817
240
0.672265796699933
270
0.67227931232405
257
0.672292827948166
243
0.672306343572283
237
0.672319859196399
248
0.672333374820516
237
0.672346890444633
248
0.672360406068749
247
0.672373921692866
237
0.672387437316982
228
0.672400952941099
242
0.672414468565215
230
0.672427984189332
239
0.672441499813448
247
0.672455015437565
232
0.672468531061681
243
0.672482046685798
261
0.672495562309914
243
0.672509077934031
253
0.672522593558147
277
0.672536109182264
275
0.67254962480638
286
0.672563140430497
274
0.672576656054614
247
0.67259017167873
261
0.672603687302847
252
0.672617202926963
223
0.67263071855108
204
0.672644234175196
188
0.672657749799313
207
0.672671265423429
178
0.672684781047546
172
0.672698296671662
183
0.672711812295779
191
0.672725327919895
164
0.672738843544012
143
0.672752359168128
137
0.672765874792245
143
0.672779390416362
126
0.672792906040478
147
0.672806421664595
135
0.672819937288711
120
0.672833452912828
129
0.672846968536944
124
0.672860484161061
124
0.672873999785177
127
0.672887515409294
121
0.67290103103341
125
0.672914546657527
122
0.672928062281643
112
0.67294157790576
137
0.672955093529876
129
0.672968609153993
111
0.672982124778109
116
0.672995640402226
122
0.673009156026343
105
0.673022671650459
123
0.673036187274576
116
0.673049702898692
108
0.673063218522809
106
0.673076734146925
101
0.673090249771042
107
0.673103765395158
103
0.673117281019275
112
0.673130796643391
93
0.673144312267508
98
0.673157827891624
109
0.673171343515741
99
0.673184859139857
102
0.673198374763974
101
0.673211890388091
108
0.673225406012207
101
0.673238921636324
86
0.67325243726044
91
0.673265952884557
98
0.673279468508673
100
0.67329298413279
108
0.673306499756906
105
0.673320015381023
90
0.673333531005139
97
0.673347046629256
89
0.673360562253372
88
0.673374077877489
94
0.673387593501605
103
0.673401109125722
96
0.673414624749839
108
0.673428140373955
96
0.673441655998072
98
0.673455171622188
101
0.673468687246305
76
0.673482202870421
79
0.673495718494538
81
0.673509234118654
79
0.673522749742771
94
0.673536265366887
81
0.673549780991004
91
0.67356329661512
81
0.673576812239237
77
0.673590327863353
72
0.67360384348747
84
0.673617359111587
75
0.673630874735703
92
0.67364439035982
89
0.673657905983936
91
0.673671421608053
98
0.673684937232169
91
0.673698452856286
76
0.673711968480402
72
0.673725484104519
72
0.673738999728635
87
0.673752515352752
102
0.673766030976868
83
0.673779546600985
90
0.673793062225101
94
0.673806577849218
94
0.673820093473335
87
0.673833609097451
75
0.673847124721568
92
0.673860640345684
97
0.673874155969801
98
0.673887671593917
92
0.673901187218034
83
0.67391470284215
84
0.673928218466267
103
0.673941734090383
91
0.6739552497145
99
0.673968765338616
108
0.673982280962733
91
0.673995796586849
108
0.674009312210966
126
0.674022827835082
146
0.674036343459199
153
0.674049859083316
140
0.674063374707432
192
0.674076890331549
223
0.674090405955665
258
0.674103921579782
327
0.674117437203898
395
0.674130952828015
455
0.674144468452131
582
0.674157984076248
705
0.674171499700364
804
0.674185015324481
939
0.674198530948597
1049
0.674212046572714
1200
0.67422556219683
1297
0.674239077820947
1357
0.674252593445064
1412
0.67426610906918
1465
0.674279624693297
1542
0.674293140317413
1444
0.67430665594153
1445
0.674320171565646
1343
0.674333687189763
1238
0.674347202813879
1177
0.674360718437996
995
0.674374234062112
900
0.674387749686229
722
0.674401265310345
612
0.674414780934462
519
0.674428296558578
432
0.674441812182695
367
0.674455327806812
308
0.674468843430928
275
0.674482359055045
240
0.674495874679161
204
0.674509390303278
199
0.674522905927394
192
0.674536421551511
203
0.674549937175627
222
0.674563452799744
257
0.67457696842386
309
0.674590484047977
411
0.674603999672093
503
0.67461751529621
546
0.674631030920327
539
0.674644546544443
612
0.67465806216856
666
0.674671577792676
580
0.674685093416793
394
0.674698609040909
194
0.674712124665026
119
0.674725640289142
92
0.674739155913259
73
0.674752671537375
74
0.674766187161492
66
0.674779702785608
66
0.674793218409725
59
0.674806734033841
65
0.674820249657958
80
0.674833765282075
66
0.674847280906191
62
0.674860796530308
O 1s
Al_foil_insulated
2020
2
6
1
28
39
1
42
File: C:\ESCApe\Data\Training\20200205_Al_foil_ARXPS.experiment
Creation
Created by : DESKTOP-MI6NA2R\kratos
Date created : 06/02/2020 01:28
Computer : DESKTOP-MI6NA2R
Location
Location ID : Al_foil_insulated
Sample : Al_foil_insulated
Description : (55.076,11.860,-0.296)mm
Tilt : 55.00
Charge Neutraliser : On
Filament Current : 0.5A
Filament Bias : 1V
Charge Balance : 4.9V
Settings
Excitation
Mode : XPS - monochromatic
Tuning : Spectroscopy
Emission current : 15.00mA
Anode library : Al
ESCA modes
Collimation : Slot
Lens : Hybrid
Resolution : 20.00
Scan
Deflection : (0.000, 0.000)mm
O 1s : 943.690-963.690eV, Sweeps 1
Start : 943.690eV
End : 963.690eV
Centre : 953.690eV
Width : 20.000eV
Step size : 0.100eV
Number Steps : 200
Dwell time : 299ms
Sweep time : 60s
Sweeps : 1
Target quality : 100
Instrument Conditions
Work function : -4.50
Acquisition Conditions
X-ray Power : 225.00W
Quality : 236.36
XPS
0
0
55
55.0755
11.8598125
-0.2956015625
Al
1486.69
100
0
0
0
0
0
0
FAT
160
0
-4.5
0
0
0
0
0
O
1s
0
Kinetic Energy
eV
943.69
0.1
2
Intensity
d
Transmission
d
pulse counting
0.298507004976273
1
0
0
0
0
0
402
0
0
0
0
825
0.694879764806946
816
0.694884779682697
809
0.694889794558448
787
0.694894809434199
807
0.694899824309951
819
0.694904839185702
749
0.694909854061453
773
0.694914868937204
814
0.694919883812955
789
0.694924898688706
749
0.694929913564458
759
0.694934928440209
756
0.69493994331596
736
0.694944958191711
735
0.694949973067462
736
0.694954987943213
742
0.694960002818964
773
0.694965017694716
748
0.694970032570467
721
0.694975047446218
759
0.694980062321969
722
0.69498507719772
716
0.694990092073471
681
0.694995106949223
744
0.695000121824974
746
0.695005136700725
702
0.695010151576476
748
0.695015166452227
698
0.695020181327978
693
0.695025196203729
662
0.695030211079481
650
0.695035225955232
672
0.695040240830983
658
0.695045255706734
650
0.695050270582485
630
0.695055285458236
651
0.695060300333987
670
0.695065315209739
634
0.69507033008549
635
0.695075344961241
654
0.695080359836992
646
0.695085374712743
646
0.695090389588494
632
0.695095404464246
580
0.695100419339997
579
0.695105434215748
618
0.695110449091499
632
0.69511546396725
609
0.695120478843001
599
0.695125493718752
634
0.695130508594504
604
0.695135523470255
599
0.695140538346006
567
0.695145553221757
566
0.695150568097508
597
0.695155582973259
540
0.695160597849011
548
0.695165612724762
570
0.695170627600513
579
0.695175642476264
554
0.695180657352015
528
0.695185672227766
528
0.695190687103517
518
0.695195701979269
509
0.69520071685502
511
0.695205731730771
495
0.695210746606522
522
0.695215761482273
480
0.695220776358024
488
0.695225791233775
494
0.695230806109527
477
0.695235820985278
469
0.695240835861029
484
0.69524585073678
480
0.695250865612531
479
0.695255880488282
461
0.695260895364034
450
0.695265910239785
433
0.695270925115536
435
0.695275939991287
436
0.695280954867038
439
0.695285969742789
447
0.69529098461854
451
0.695295999494292
426
0.695301014370043
423
0.695306029245794
417
0.695311044121545
418
0.695316058997296
398
0.695321073873047
401
0.695326088748799
400
0.69533110362455
392
0.695336118500301
382
0.695341133376052
371
0.695346148251803
362
0.695351163127554
387
0.695356178003305
390
0.695361192879057
362
0.695366207754808
388
0.695371222630559
385
0.69537623750631
399
0.695381252382061
364
0.695386267257812
372
0.695391282133563
370
0.695396297009315
378
0.695401311885066
358
0.695406326760817
366
0.695411341636568
366
0.695416356512319
338
0.69542137138807
356
0.695426386263822
361
0.695431401139573
396
0.695436416015324
369
0.695441430891075
416
0.695446445766826
371
0.695451460642577
370
0.695456475518328
394
0.69546149039408
418
0.695466505269831
392
0.695471520145582
426
0.695476535021333
431
0.695481549897084
397
0.695486564772835
403
0.695491579648587
442
0.695496594524338
488
0.695501609400089
495
0.69550662427584
504
0.695511639151591
507
0.695516654027342
558
0.695521668903093
606
0.695526683778845
641
0.695531698654596
745
0.695536713530347
786
0.695541728406098
908
0.695546743281849
1012
0.6955517581576
1092
0.695556773033352
1239
0.695561787909103
1379
0.695566802784854
1564
0.695571817660605
1791
0.695576832536356
1997
0.695581847412107
2290
0.695586862287858
2563
0.69559187716361
2883
0.695596892039361
3021
0.695601906915112
3275
0.695606921790863
3710
0.695611936666614
4022
0.695616951542365
4251
0.695621966418116
4541
0.695626981293868
4663
0.695631996169619
4719
0.69563701104537
4892
0.695642025921121
5117
0.695647040796872
5219
0.695652055672623
5153
0.695657070548375
5212
0.695662085424126
5227
0.695667100299877
5073
0.695672115175628
5117
0.695677130051379
4964
0.69568214492713
4764
0.695687159802881
4649
0.695692174678633
4474
0.695697189554384
4282
0.695702204430135
4046
0.695707219305886
3825
0.695712234181637
3518
0.695717249057388
3109
0.69572226393314
2833
0.695727278808891
2486
0.695732293684642
2227
0.695737308560393
1968
0.695742323436144
1686
0.695747338311895
1466
0.695752353187646
1251
0.695757368063398
1115
0.695762382939149
921
0.6957673978149
826
0.695772412690651
693
0.695777427566402
593
0.695782442442153
541
0.695787457317904
517
0.695792472193656
479
0.695797487069407
443
0.695802501945158
401
0.695807516820909
417
0.69581253169666
372
0.695817546572411
344
0.695822561448163
369
0.695827576323914
348
0.695832591199665
348
0.695837606075416
348
0.695842620951167
364
0.695847635826918
327
0.695852650702669
324
0.695857665578421
338
0.695862680454172
331
0.695867695329923
324
0.695872710205674
348
0.695877725081425
314
0.695882739957176
C 1s
Al_foil_insulated
2020
2
6
1
28
39
1
42
File: C:\ESCApe\Data\Training\20200205_Al_foil_ARXPS.experiment
Creation
Created by : DESKTOP-MI6NA2R\kratos
Date created : 06/02/2020 01:28
Computer : DESKTOP-MI6NA2R
Location
Location ID : Al_foil_insulated
Sample : Al_foil_insulated
Description : (55.076,11.860,-0.296)mm
Tilt : 55.00
Charge Neutraliser : On
Filament Current : 0.5A
Filament Bias : 1V
Charge Balance : 4.9V
Settings
Excitation
[...]
60
0.672806421664595
65
0.672819937288711
62
0.672833452912828
75
0.672846968536944
71
0.672860484161061
71
0.672873999785177
59
0.672887515409294
65
0.67290103103341
68
0.672914546657527
70
0.672928062281643
77
0.67294157790576
55
0.672955093529876
72
0.672968609153993
63
0.672982124778109
62
0.672995640402226
59
0.673009156026343
61
0.673022671650459
56
0.673036187274576
66
0.673049702898692
76
0.673063218522809
68
0.673076734146925
59
0.673090249771042
59
0.673103765395158
61
0.673117281019275
62
0.673130796643391
68
0.673144312267508
64
0.673157827891624
54
0.673171343515741
47
0.673184859139857
45
0.673198374763974
56
0.673211890388091
58
0.673225406012207
66
0.673238921636324
63
0.67325243726044
59
0.673265952884557
56
0.673279468508673
51
0.67329298413279
59
0.673306499756906
47
0.673320015381023
45
0.673333531005139
61
0.673347046629256
54
0.673360562253372
56
0.673374077877489
51
0.673387593501605
57
0.673401109125722
55
0.673414624749839
59
0.673428140373955
51
0.673441655998072
68
0.673455171622188
56
0.673468687246305
52
0.673482202870421
54
0.673495718494538
58
0.673509234118654
48
0.673522749742771
38
0.673536265366887
48
0.673549780991004
51
0.67356329661512
56
0.673576812239237
51
0.673590327863353
53
0.67360384348747
46
0.673617359111587
54
0.673630874735703
52
0.67364439035982
49
0.673657905983936
46
0.673671421608053
53
0.673684937232169
54
0.673698452856286
44
0.673711968480402
44
0.673725484104519
43
0.673738999728635
45
0.673752515352752
42
0.673766030976868
38
0.673779546600985
39
0.673793062225101
43
0.673806577849218
42
0.673820093473335
47
0.673833609097451
54
0.673847124721568
59
0.673860640345684
48
0.673874155969801
48
0.673887671593917
52
0.673901187218034
59
0.67391470284215
59
0.673928218466267
62
0.673941734090383
51
0.6739552497145
54
0.673968765338616
47
0.673982280962733
53
0.673995796586849
47
0.674009312210966
64
0.674022827835082
68
0.674036343459199
80
0.674049859083316
76
0.674063374707432
100
0.674076890331549
106
0.674090405955665
137
0.674103921579782
163
0.674117437203898
194
0.674130952828015
208
0.674144468452131
252
0.674157984076248
321
0.674171499700364
379
0.674185015324481
432
0.674198530948597
511
0.674212046572714
575
0.67422556219683
582
0.674239077820947
636
0.674252593445064
713
0.67426610906918
713
0.674279624693297
731
0.674293140317413
757
0.67430665594153
711
0.674320171565646
645
0.674333687189763
645
0.674347202813879
571
0.674360718437996
491
0.674374234062112
439
0.674387749686229
390
0.674401265310345
312
0.674414780934462
263
0.674428296558578
211
0.674441812182695
181
0.674455327806812
159
0.674468843430928
132
0.674482359055045
103
0.674495874679161
94
0.674509390303278
95
0.674522905927394
103
0.674536421551511
81
0.674549937175627
78
0.674563452799744
87
0.67457696842386
88
0.674590484047977
102
0.674603999672093
120
0.67461751529621
129
0.674631030920327
136
0.674644546544443
158
0.67465806216856
161
0.674671577792676
152
0.674685093416793
113
0.674698609040909
75
0.674712124665026
61
0.674725640289142
45
0.674739155913259
39
0.674752671537375
51
0.674766187161492
44
0.674779702785608
40
0.674793218409725
43
0.674806734033841
35
0.674820249657958
38
0.674833765282075
38
0.674847280906191
39
0.674860796530308
O 1s
Al_foil_insulated
2020
2
6
1
36
39
1
42
File: C:\ESCApe\Data\Training\20200205_Al_foil_ARXPS.experiment
Creation
Created by : DESKTOP-MI6NA2R\kratos
Date created : 06/02/2020 01:36
Computer : DESKTOP-MI6NA2R
Location
Location ID : Al_foil_insulated
Sample : Al_foil_insulated
Description : (55.076,11.860,-0.296)mm
Tilt : 70.00
Charge Neutraliser : On
Filament Current : 0.5A
Filament Bias : 1V
Charge Balance : 4.9V
Settings
Excitation
Mode : XPS - monochromatic
Tuning : Spectroscopy
Emission current : 15.00mA
Anode library : Al
ESCA modes
Collimation : Slot
Lens : Hybrid
Resolution : 20.00
Scan
Deflection : (0.000, 0.000)mm
O 1s : 943.690-963.690eV, Sweeps 1
Start : 943.690eV
End : 963.690eV
Centre : 953.690eV
Width : 20.000eV
Step size : 0.100eV
Number Steps : 200
Dwell time : 299ms
Sweep time : 60s
Sweeps : 1
Target quality : 100
Instrument Conditions
Work function : -4.50
Acquisition Conditions
X-ray Power : 225.00W
Quality : 151.64
XPS
0
0
70
55.0755
11.8598125
-0.2956015625
Al
1486.69
100
0
0
0
0
0
0
FAT
160
0
-4.5
0
0
0
0
0
O
1s
0
Kinetic Energy
eV
943.69
0.1
2
Intensity
d
Transmission
d
pulse counting
0.298507004976273
1
0
0
0
0
0
402
0
0
0
0
460
0.694879764806946
448
0.694884779682697
451
0.694889794558448
474
0.694894809434199
430
0.694899824309951
437
0.694904839185702
449
0.694909854061453
406
0.694914868937204
394
0.694919883812955
401
0.694924898688706
408
0.694929913564458
377
0.694934928440209
403
0.69493994331596
424
0.694944958191711
393
0.694949973067462
377
0.694954987943213
381
0.694960002818964
392
0.694965017694716
388
0.694970032570467
383
0.694975047446218
393
0.694980062321969
352
0.69498507719772
368
0.694990092073471
362
0.694995106949223
393
0.695000121824974
379
0.695005136700725
335
0.695010151576476
338
0.695015166452227
326
0.695020181327978
332
0.695025196203729
321
0.695030211079481
341
0.695035225955232
329
0.695040240830983
340
0.695045255706734
345
0.695050270582485
344
0.695055285458236
337
0.695060300333987
348
0.695065315209739
339
0.69507033008549
311
0.695075344961241
321
0.695080359836992
338
0.695085374712743
325
0.695090389588494
358
0.695095404464246
344
0.695100419339997
333
0.695105434215748
320
0.695110449091499
324
0.69511546396725
345
0.695120478843001
339
0.695125493718752
317
0.695130508594504
285
0.695135523470255
297
0.695140538346006
313
0.695145553221757
281
0.695150568097508
273
0.695155582973259
282
0.695160597849011
263
0.695165612724762
280
0.695170627600513
291
0.695175642476264
293
0.695180657352015
274
0.695185672227766
245
0.695190687103517
257
0.695195701979269
253
0.69520071685502
255
0.695205731730771
282
0.695210746606522
259
0.695215761482273
254
0.695220776358024
263
0.695225791233775
268
0.695230806109527
240
0.695235820985278
254
0.695240835861029
266
0.69524585073678
236
0.695250865612531
238
0.695255880488282
234
0.695260895364034
246
0.695265910239785
220
0.695270925115536
228
0.695275939991287
229
0.695280954867038
204
0.695285969742789
207
0.69529098461854
217
0.695295999494292
219
0.695301014370043
209
0.695306029245794
208
0.695311044121545
211
0.695316058997296
208
0.695321073873047
210
0.695326088748799
185
0.69533110362455
196
0.695336118500301
203
0.695341133376052
204
0.695346148251803
200
0.695351163127554
203
0.695356178003305
206
0.695361192879057
208
0.695366207754808
192
0.695371222630559
188
0.69537623750631
184
0.695381252382061
185
0.695386267257812
204
0.695391282133563
208
0.695396297009315
195
0.695401311885066
194
0.695406326760817
185
0.695411341636568
190
0.695416356512319
202
0.69542137138807
164
0.695426386263822
183
0.695431401139573
166
0.695436416015324
183
0.695441430891075
205
0.695446445766826
205
0.695451460642577
165
0.695456475518328
171
0.69546149039408
197
0.695466505269831
206
0.695471520145582
211
0.695476535021333
224
0.695481549897084
213
0.695486564772835
219
0.695491579648587
223
0.695496594524338
216
0.695501609400089
219
0.69550662427584
264
0.695511639151591
257
0.695516654027342
303
0.695521668903093
318
0.695526683778845
329
0.695531698654596
367
0.695536713530347
407
0.695541728406098
424
0.695546743281849
492
0.6955517581576
541
0.695556773033352
631
0.695561787909103
727
0.695566802784854
778
0.695571817660605
846
0.695576832536356
1004
0.695581847412107
1162
0.695586862287858
1260
0.69559187716361
1376
0.695596892039361
1507
0.695601906915112
1613
0.695606921790863
1754
0.695611936666614
1895
0.695616951542365
1984
0.695621966418116
2106
0.695626981293868
2218
0.695631996169619
2344
0.69563701104537
2306
0.695642025921121
2284
0.695647040796872
2362
0.695652055672623
2303
0.695657070548375
2268
0.695662085424126
2259
0.695667100299877
2228
0.695672115175628
2157
0.695677130051379
2167
0.69568214492713
2069
0.695687159802881
1941
0.695692174678633
1904
0.695697189554384
1730
0.695702204430135
1645
0.695707219305886
1611
0.695712234181637
1371
0.695717249057388
1248
0.69572226393314
1195
0.695727278808891
1109
0.695732293684642
964
0.695737308560393
829
0.695742323436144
748
0.695747338311895
673
0.695752353187646
533
0.695757368063398
478
0.695762382939149
418
0.6957673978149
364
0.695772412690651
347
0.695777427566402
295
0.695782442442153
275
0.695787457317904
242
0.695792472193656
243
0.695797487069407
220
0.695802501945158
195
0.695807516820909
196
0.69581253169666
187
0.695817546572411
168
0.695822561448163
177
0.695827576323914
163
0.695832591199665
193
0.695837606075416
164
0.695842620951167
163
0.695847635826918
171
0.695852650702669
178
0.695857665578421
194
0.695862680454172
157
0.695867695329923
165
0.695872710205674
153
0.695877725081425
159
0.695882739957176
C 1s
Al_foil_insulated
2020
2
6
1
36
39
1
42
File: C:\ESCApe\Data\Training\20200205_Al_foil_ARXPS.experiment
Creation
Created by : DESKTOP-MI6NA2R\kratos
Date created : 06/02/2020 01:36
Computer : DESKTOP-MI6NA2R
Location
Location ID : Al_foil_insulated
Sample : Al_foil_insulated
Description : (55.076,11.860,-0.296)mm
Tilt : 70.00
Charge Neutraliser : On
Filament Current : 0.5A
Filament Bias : 1V
Charge Balance : 4.9V
Settings
Excitation
Mode : XPS - monochromatic
Tuning : Spectroscopy
Emission current : 15.00mA
Anode library : Al
ESCA modes
Collimation : Slot
Lens : Hybrid
Resolution : 20.00
Scan
Deflection : (0.000, 0.000)mm
C 1s : 1191.690-1211.690eV, Sweeps 1
Start : 1191.690eV
End : 1211.690eV
Centre : 1201.690eV
Width : 20.000eV
Step size : 0.100eV
Number Steps : 200
Dwell time : 299ms
Sweep time : 60s
Sweeps : 1
Target quality : 100
Instrument Conditions
Work function : -4.50
Acquisition Conditions
X-ray Power : 225.00W
Quality : 105.37
XPS
0
0
70
55.0755
11.8598125
-0.2956015625
Al
1486.69
100
0
0
0
0
0
0
FAT
160
0
-4.5
0
0
0
0
0
C
1s
0
Kinetic Energy
eV
1191.69
0.1
2
Intensity
d
Transmission
d
pulse counting
0.298507988452911
1
0
0
0
0
0
402
0
0
0
0
191
0.677919839607315
197
0.677933989241674
212
0.677948138876032
200
0.67796228851039
208
0.677976438144748
211
0.677990587779106
189
0.678004737413464
192
0.678018887047823
215
0.678033036682181
198
0.678047186316539
194
0.678061335950897
201
0.678075485585255
210
0.678089635219613
193
0.678103784853971
205
0.678117934488329
205
0.678132084122688
191
0.678146233757046
190
0.678160383391404
195
0.678174533025762
224
0.67818868266012
191
0.678202832294478
189
0.678216981928837
198
0.678231131563195
192
0.678245281197553
188
0.678259430831911
192
0.678273580466269
184
0.678287730100627
182
0.678301879734985
201
0.678316029369343
178
0.678330179003702
187
0.67834432863806
192
0.678358478272418
182
0.678372627906776
198
0.678386777541134
199
0.678400927175492
195
0.67841507680985
172
0.678429226444209
183
0.678443376078567
174
0.678457525712925
187
0.678471675347283
180
0.678485824981641
186
0.678499974615999
172
0.678514124250357
163
0.678528273884716
169
0.678542423519074
168
0.678556573153432
157
0.67857072278779
165
0.678584872422148
187
0.678599022056506
183
0.678613171690864
181
0.678627321325223
178
0.678641470959581
163
0.678655620593939
186
0.678669770228297
162
0.678683919862655
170
0.678698069497013
167
0.678712219131371
177
0.67872636876573
170
0.678740518400088
158
0.678754668034446
175
0.678768817668804
164
0.678782967303162
163
0.67879711693752
172
0.678811266571878
189
0.678825416206237
162
0.678839565840595
169
0.678853715474953
164
0.678867865109311
169
0.678882014743669
155
0.678896164378027
167
0.678910314012385
173
0.678924463646744
173
0.678938613281102
160
0.67895276291546
166
0.678966912549818
171
0.678981062184176
164
0.678995211818534
161
0.679009361452892
185
0.679023511087251
190
0.679037660721609
170
0.679051810355967
190
0.679065959990325
195
0.679080109624683
185
0.679094259259041
193
0.679108408893399
195
0.679122558527757
193
0.679136708162116
182
0.679150857796474
191
0.679165007430832
180
0.67917915706519
192
0.679193306699548
178
0.679207456333906
199
0.679221605968265
194
0.679235755602623
211
0.679249905236981
217
0.679264054871339
229
0.679278204505697
239
0.679292354140055
242
0.679306503774413
242
0.679320653408771
248
0.67933480304313
228
0.679348952677488
254
0.679363102311846
242
0.679377251946204
245
0.679391401580562
260
0.67940555121492
249
0.679419700849278
227
0.679433850483637
240
0.679448000117995
231
0.679462149752353
259
0.679476299386711
232
0.679490449021069
218
0.679504598655427
218
0.679518748289785
204
0.679532897924144
220
0.679547047558502
225
0.67956119719286
207
0.679575346827218
203
0.679589496461576
217
0.679603646095934
248
0.679617795730292
247
0.679631945364651
258
0.679646094999009
291
0.679660244633367
298
0.679674394267725
294
0.679688543902083
315
0.679702693536441
318
0.679716843170799
380
0.679730992805158
374
0.679745142439516
467
0.679759292073874
501
0.679773441708232
562
0.67978759134259
659
0.679801740976948
824
0.679815890611306
921
0.679830040245665
971
0.679844189880023
1100
0.679858339514381
1224
0.679872489148739
1254
0.679886638783097
1394
0.679900788417455
1402
0.679914938051813
1287
0.679929087686172
1259
0.67994323732053
1157
0.679957386954888
1132
0.679971536589246
980
0.679985686223604
903
0.679999835857962
798
0.68001398549232
648
0.680028135126679
541
0.680042284761037
486
0.680056434395395
415
0.680070584029753
333
0.680084733664111
266
0.680098883298469
221
0.680113032932827
216
0.680127182567186
209
0.680141332201544
194
0.680155481835902
174
0.68016963147026
176
0.680183781104618
157
0.680197930738976
160
0.680212080373334
152
0.680226230007693
164
0.680240379642051
165
0.680254529276409
166
0.680268678910767
143
0.680282828545125
141
0.680296978179483
136
0.680311127813841
153
0.680325277448199
148
0.680339427082558
147
0.680353576716916
133
0.680367726351274
144
0.680381875985632
144
0.68039602561999
158
0.680410175254348
146
0.680424324888707
132
0.680438474523065
154
0.680452624157423
147
0.680466773791781
152
0.680480923426139
146
0.680495073060497
134
0.680509222694855
138
0.680523372329213
159
0.680537521963572
150
0.68055167159793
154
0.680565821232288
145
0.680579970866646
145
0.680594120501004
139
0.680608270135362
131
0.68062241976972
131
0.680636569404079
131
0.680650719038437
133
0.680664868672795
148
0.680679018307153
138
0.680693167941511
155
0.680707317575869
140
0.680721467210227
157
0.680735616844586
156
0.680749766478944
Al 2p
Al_foil_insulated
2020
2
6
1
36
39
1
42
File: C:\ESCApe\Data\Training\20200205_Al_foil_ARXPS.experiment
Creation
Created by : DESKTOP-MI6NA2R\kratos
Date created : 06/02/2020 01:36
Computer : DESKTOP-MI6NA2R
Location
Location ID : Al_foil_insulated
Sample : Al_foil_insulated
Description : (55.076,11.860,-0.296)mm
Tilt : 70.00
Charge Neutraliser : On
Filament Current : 0.5A
Filament Bias : 1V
Charge Balance : 4.9V
Settings
Excitation
Mode : XPS - monochromatic
Tuning : Spectroscopy
Emission current : 15.00mA
Anode library : Al
ESCA modes
Collimation : Slot
Lens : Hybrid
Resolution : 20.00
Scan
Deflection : (0.000, 0.000)mm
Al 2p : 1400.690-1420.690eV, Sweeps 3
Start : 1400.690eV
End : 1420.690eV
Centre : 1410.690eV
Width : 20.000eV
Step size : 0.100eV
Number Steps : 200
Dwell time : 299ms
Sweep time : 60s
Sweeps : 3
Target quality : 100
Instrument Conditions
Work function : -4.50
Acquisition Conditions
X-ray Power : 225.00W
Quality : 131.09
XPS
0
0
70
55.0755
11.8598125
-0.2956015625
Al
1486.69
100
0
0
0
0
0
0
FAT
160
0
-4.5
0
0
0
0
0
Al
2p
0
Kinetic Energy
eV
1400.69
0.1
2
Intensity
d
Transmission
d
pulse counting
0.895521014928818
1
0
0
0
0
0
402
0
0
0
0
204
0.672157671707001
196
0.672171187331118
200
0.672184702955234
191
0.672198218579351
193
0.672211734203467
199
0.672225249827584
191
0.6722387654517
187
0.672252281075817
208
0.672265796699933
213
0.67227931232405
214
0.672292827948166
191
0.672306343572283
195
0.672319859196399
188
0.672333374820516
194
0.672346890444633
187
0.672360406068749
181
0.672373921692866
186
0.672387437316982
189
0.672400952941099
175
0.672414468565215
173
0.672427984189332
177
0.672441499813448
186
0.672455015437565
194
0.672468531061681
199
0.672482046685798
178
0.672495562309914
168
0.672509077934031
164
0.672522593558147
179
0.672536109182264
165
0.67254962480638
168
0.672563140430497
172
0.672576656054614
158
0.67259017167873
165
0.672603687302847
152
0.672617202926963
171
0.67263071855108
153
0.672644234175196
163
0.672657749799313
152
0.672671265423429
155
0.672684781047546
122
0.672698296671662
127
0.672711812295779
138
0.672725327919895
138
0.672738843544012
151
0.672752359168128
143
0.672765874792245
145
0.672779390416362
130
0.672792906040478
113
0.672806421664595
110
0.672819937288711
124
0.672833452912828
125
0.672846968536944
136
0.672860484161061
123
0.672873999785177
113
0.672887515409294
128
0.67290103103341
121
0.672914546657527
117
0.672928062281643
124
0.67294157790576
133
0.672955093529876
126
0.672968609153993
127
0.672982124778109
112
0.672995640402226
115
0.673009156026343
117
0.673022671650459
118
0.673036187274576
128
0.673049702898692
111
0.673063218522809
119
0.673076734146925
115
0.673090249771042
108
0.673103765395158
114
0.673117281019275
102
0.673130796643391
96
0.673144312267508
115
0.673157827891624
107
0.673171343515741
109
0.673184859139857
114
0.673198374763974
104
0.673211890388091
102
0.673225406012207
113
0.673238921636324
107
0.67325243726044
101
0.673265952884557
106
0.673279468508673
108
0.67329298413279
106
0.673306499756906
102
0.673320015381023
92
0.673333531005139
101
0.673347046629256
108
0.673360562253372
98
0.673374077877489
92
0.673387593501605
100
0.673401109125722
110
0.673414624749839
84
0.673428140373955
94
0.673441655998072
99
0.673455171622188
92
0.673468687246305
95
0.673482202870421
96
0.673495718494538
104
0.673509234118654
95
0.673522749742771
88
0.673536265366887
89
0.673549780991004
82
0.67356329661512
95
0.673576812239237
106
0.673590327863353
100
0.67360384348747
94
0.673617359111587
100
0.673630874735703
100
0.67364439035982
92
0.673657905983936
86
0.673671421608053
94
0.673684937232169
103
0.673698452856286
99
0.673711968480402
93
0.673725484104519
96
0.673738999728635
95
0.673752515352752
101
0.673766030976868
88
0.673779546600985
102
0.673793062225101
102
0.673806577849218
119
0.673820093473335
103
0.673833609097451
88
0.673847124721568
101
0.673860640345684
99
0.673874155969801
94
0.673887671593917
94
0.673901187218034
96
0.67391470284215
108
0.673928218466267
98
0.673941734090383
98
0.6739552497145
109
0.673968765338616
118
0.673982280962733
116
0.673995796586849
102
0.674009312210966
112
0.674022827835082
137
0.674036343459199
138
0.674049859083316
158
0.674063374707432
170
0.674076890331549
199
0.674090405955665
256
0.674103921579782
300
0.674117437203898
345
0.674130952828015
410
0.674144468452131
488
0.674157984076248
538
0.674171499700364
621
0.674185015324481
739
0.674198530948597
871
0.674212046572714
927
0.67422556219683
970
0.674239077820947
1104
0.674252593445064
1123
0.67426610906918
1145
0.674279624693297
1191
0.674293140317413
1163
0.67430665594153
1092
0.674320171565646
1098
0.674333687189763
993
0.674347202813879
932
0.674360718437996
830
0.674374234062112
721
0.674387749686229
611
0.674401265310345
532
0.674414780934462
457
0.674428296558578
389
0.674441812182695
334
0.674455327806812
251
0.674468843430928
209
0.674482359055045
191
0.674495874679161
162
0.674509390303278
159
0.674522905927394
136
0.674536421551511
127
0.674549937175627
119
0.674563452799744
120
0.67457696842386
137
0.674590484047977
152
0.674603999672093
192
0.67461751529621
195
0.674631030920327
212
0.674644546544443
193
0.67465806216856
222
0.674671577792676
197
0.674685093416793
156
0.674698609040909
129
0.674712124665026
105
0.674725640289142
97
0.674739155913259
99
0.674752671537375
91
0.674766187161492
115
0.674779702785608
116
0.674793218409725
98
0.674806734033841
84
0.674820249657958
80
0.674833765282075
83
0.674847280906191
98
0.674860796530308
end of experiment