File: src/parser/__tests__/data/survey.vms
VAMAS Surface Chemical Analysis Standard Data Transfer Format 1988 May 4
Not specified
MI-600-BE9240AA
DESKTOP-MI6NA2R\kratos
20200205_Al_foil_ARXPS.experiment
0
NORM
REGULAR
1
4
Index
d
PositionX [mm]
n
PositionY [mm]
n
PositionZ [mm]
n
0
0
0
0
1
wide
Al_foil_grounded
2020
2
5
15
56
4
1
36
Creation
Created by : DESKTOP-MI6NA2R\kratos
Date created : 05/02/2020 15:56
Computer : DESKTOP-MI6NA2R
Location
Location ID : Al_foil_grounded
Sample : Al_foil_grounded
Description : (33.028,11.809,-0.189)mm
Tilt : 0.00
Charge Neutraliser : Off
Settings
Excitation
Mode : XPS - monochromatic
Tuning : Spectroscopy
Emission current : 15.00mA
Anode library : Al
ESCA modes
Collimation : Slot
Lens : Hybrid
Resolution : 160.00
Scan
Deflection : (0.000, 0.000)mm
wide : 286.690-1491.690eV, Sweeps 1
Start : 286.690eV
End : 1491.690eV
Centre : 889.190eV
Width : 1205.000eV
Step size : 1.000eV
Number Steps : 1205
Dwell time : 100ms
Sweep time : 120s
Sweeps : 1
Instrument Conditions
Work function : -4.50
Acquisition Conditions
X-ray Power : 225.00W
XPS
1
33.02775
11.80921875
-0.188890625
Al (mono)
1486.69
225
1E+37
1E+37
1E+37
1E+37
FAT
160
1E+37
-4.5
1E+37
1E+37
1E+37
1E+37
1E+37
wide

-1
Kinetic energy
eV
286.69
1
2
Intensity
d
Transmission
d
pulse counting
0.0995024875621891
0
1E+37
0
1
12.1974630554708
11672
11752
11705
11639
11746
11528
11439
11607
11655
11786
12011
11789
11920
11881
12062
12091
11955
12006
11941
12016
11996
11928
12131
12159
12280
12213
12314
12214
12237
12308
12365
12244
12276
12347
12308
12503
12601
12616
12549
12492
12539
12813
12713
12594
12808
12928
12886
12774
12870
12840
13007
13004
12947
13205
13089
13173
13195
13111
13175
13150
13201
13278
13412
13487
13496
13465
13461
13493
13598
13756
13662
13618
13703
13742
13857
13945
13819
13919
13900
13892
14058
14144
14008
14272
14184
14390
14121
14228
14403
14416
14358
14310
14456
14472
14552
14508
14304
14492
14782
14865
14677
14769
14581
14776
14885
14991
14916
14950
14998
15019
14976
15176
15245
15364
15285
15466
15601
15470
15539
15555
15628
15798
15725
15758
15707
15791
15967
16072
16016
16108
16125
16257
16366
16521
16432
16473
16409
16695
16858
16949
16788
16959
16765
17013
17135
17075
17182
17417
17448
17453
17427
17747
17536
17683
17887
17770
18266
18113
17863
18066
18333
18380
18393
18329
18591
18486
18468
18667
19058
18963
19131
19170
18943
19048
19410
19585
19628
19929
19950
20148
20461
20668
20589
20649
20882
20864
20761
20764
20536
20335
20284
20342
20415
20916
21090
21782
22561
23010
23575
24237
24220
23975
23139
21825
21071
20336
19971
19340
18330
17770
17476
16991
17136
17113
17536
18532
20326
22697
25291
27935
29934
30487
29444
26365
23319
20914
19195
18005
16536
15034
13769
12196
10760
9556
8647
7930
7715
7625
7596
7559
7388
7449
7314
7264
7221
7398
7366
7459
7250
7127
7280
7236
7285
7363
7311
7371
7293
7450
7248
7345
7346
7358
7412
7359
7437
7343
7325
7300
7308
7295
7336
7271
7305
7406
7389
7408
7360
7329
7376
7373
7325
7470
7449
7400
7564
7632
7568
7479
7252
7362
7429
7438
7447
7489
7536
7454
7433
7391
7391
7476
7403
7506
7446
7469
7510
7554
7486
7388
7426
7496
7515
7654
7535
7479
7607
7421
7450
7405
7441
7525
7458
7638
7594
7681
7570
7527
7619
7588
7612
7628
7800
7635
7564
7607
7655
7634
7617
7598
7499
7693
7821
7778
7661
7531
7627
7688
7665
7601
7587
7700
7696
7568
7588
7655
7627
7759
7822
7771
7791
7764
7658
7806
7734
7804
7871
7848
7749
7724
7828
7792
7823
7754
7810
7872
7918
7924
7872
7804
7806
7788
7916
7996
7975
7818
7908
7892
8008
7882
7924
8012
7993
8004
7918
8039
8050
8180
7990
7984
8088
8094
8014
8052
8017
8034
8082
8001
8098
8020
8093
8120
8133
8207
8137
8230
8115
8162
8119
8141
8253
8160
8341
8112
8100
8233
8227
8404
8419
8319
8181
8390
8378
8317
8278
8312
8327
8347
8419
8446
8434
8509
8566
8598
8415
8455
8565
8588
8495
8626
8584
8553
8425
8509
8515
8532
8577
8689
8571
8682
8623
8630
8586
8758
8694
8708
8811
8909
8761
8820
8745
8788
8705
8713
8738
8896
8930
9070
8862
8977
8947
8988
8916
9058
9064
9192
9345
9127
9021
9162
9143
9194
9390
9425
9403
9237
9185
9347
9239
9248
9352
9279
9286
9443
9453
9494
9409
9590
9522
9459
9476
9706
9723
9661
9480
9596
9750
9705
9861
9772
9723
9690
9823
9906
9956
9873
10055
9938
9778
10033
10058
10003
10089
10094
10206
10294
10180
10270
10295
10252
10361
10296
10314
10434
10446
10640
10525
10501
10644
10820
10487
10569
10599
10615
10879
10866
10952
10962
10883
10828
11040
11110
10957
11142
11146
11178
11317
11445
11224
11315
11381
11644
11570
11533
11648
11736
11564
11700
11612
11762
11934
11964
11880
11944
12109
12266
12111
12184
12282
12228
12516
12408
12445
12495
12597
12462
12591
12648
12726
12755
12854
13074
12998
13064
13092
13154
13299
13278
13465
13553
13378
13485
13577
13535
13725
13718
13810
14069
14074
14053
14301
14355
14530
14536
14430
14406
14338
14392
14410
14297
14291
14550
14320
14440
14563
14379
14427
14398
14608
14968
15365
16024
16704
17476
18096
18575
18708
18721
18059
17395
16461
15251
14420
13568
12790
12512
11819
11089
10301
9701
9296
8703
8344
7842
7891
8619
10787
17457
37254
68854
81848
57242
24270
9879
6953
6402
6231
6022
5852
5782
5614
5755
5716
5633
5670
5692
5760
5689
5632
5740
5649
5682
5650
5785
5682
5610
5705
5644
5653
5738
5751
5749
5678
5727
5748
5711
5695
5615
5753
5713
5702
5707
5833
5685
5769
5735
5735
5675
5761
5728
5652
5745
5727
5800
5788
5736
5692
5721
5602
5714
5707
5805
5695
5678
5794
5678
5674
5709
5787
5798
5763
5764
5697
5847
5823
5862
5865
5879
5837
5734
5764
5855
5811
5841
5776
5845
5857
5823
5831
5959
6037
5987
5971
5943
5861
5844
5837
5845
5913
5959
5996
6016
5946
5992
6026
5909
5976
6060
5974
5891
5852
6011
5954
6025
5942
5996
6015
5994
5995
6011
5956
6021
6099
6117
6223
6166
6042
6104
6135
6067
6108
6300
6273
6093
6128
6146
6213
6057
6161
6106
6071
6183
6153
6185
6153
6174
6317
6383
6126
6217
6184
6267
6279
6293
6283
6345
6366
6214
6298
6341
6305
6202
6349
6380
6331
6323
6371
6423
6313
6407
6360
6239
6373
6405
6444
6402
6418
6499
6618
6758
6896
6845
6642
6949
6764
6660
6354
6535
6422
6386
6566
6643
6473
6621
6583
6697
6701
6588
6662
6718
6573
6793
6800
6907
6846
6733
6574
6686
6763
6780
6754
6735
6650
6865
6860
6768
6722
6635
6700
6856
6877
6981
7203
7400
7900
8308
8165
7515
7136
6865
6715
6541
6500
6392
6187
6148
6177
6095
6209
6192
6164
6608
7370
7590
8005
11375
15998
13196
8094
6270
5989
5860
5861
5889
5862
5810
5788
5898
5870
5960
5940
5952
5828
5803
5797
5632
5919
5864
5850
5928
5874
5847
5804
5885
5945
5928
5906
5884
5943
5904
5872
6019
6048
5998
6035
6008
6025
6008
6082
6199
6043
6066
5957
5854
6047
5983
5962
5970
6111
6147
6177
6022
6074
5995
6144
6073
6114
6075
6077
6114
6131
6086
6043
6141
6153
6158
6147
6222
6152
6178
6171
6138
6131
6140
6232
6263
6209
6215
6220
6213
6163
6261
6350
6415
6371
6345
6367
6270
6305
6221
6243
6303
6354
6271
6376
6481
6417
6428
6381
6440
6470
6548
6490
6608
6439
6330
6375
6406
6491
6523
6555
6474
6575
6658
6628
6535
6712
6784
6791
6540
6318
6361
6216
6338
6300
6280
6444
6652
6802
6817
6852
6972
7119
7069
6857
6422
6355
6319
6291
6406
6488
6434
6485
6338
6451
6359
6407
6638
7017
6999
6159
5051
4477
4305
4123
4091
4120
4146
4436
5100
6977
11716
16541
15480
12324
8662
5216
3806
3365
3235
3212
3067
2992
3073
3079
3110
3143
3310
3543
3555
3324
2937
2880
2981
3016
2855
2811
2830
2813
2780
2786
2875
3212
3448
3479
2745
1896
1476
1272
1144
1076
1075
1098
1277
1563
2819
7319
11129
8574
6189
4304
1515
675
642
625
598
599
609
609
618
610
621
649
644
640
685
709
703
691
800
856
926
897
828
791
771
766
760
702
684
640
648
643
623
628
643
628
624
634
639
700
752
816
953
1159
1495
1918
2390
2494
1936
1162
724
524
423
370
327
337
332
340
408
573
739
710
752
703
732
678
444
228
142
152
123
88
27
3
1
4
1
15.5208295946116
end of experiment